Workbook

Sheet Eval 1
A1: Activité intégrative : itération 1
M2: Acquis évalués : | N2: 1 | O2: 2 | P2: 3 | Q2: 4
A3: Nom et prénom : | C3: Thomas Hausmann | M3: Statut (Acquis=1, Non-acquis=0) | N3: =IF(OR(AND($O$5=($N$5+1),$K$10=0),$N$5=$O$5),TRUNC($N$15/$O$15),0) -> 0 | O3: =IF(OR(AND($O$5=($N$5+1),$K$10=0),$N$5=$O$5),TRUNC($N$27/$O$27),0) -> 0 | P3: =IF(OR(AND($O$5=($N$5+1),$K$10=0),$N$5=$O$5),TRUNC($N$32/$O$32),0) -> 0 | Q3: =IF(OR(AND($O$5=($N$5+1),$K$10=0),$N$5=$O$5),TRUNC($N$40/$O$40),0) -> 0
S4: AI-1 : Lancer une partie
A5: Préalable | K5: Observé (oui=1, non = 0) | M5: Total préalable | N5: =IF($M$12<=2,SUM($K$7:$K$14), 0) -> 0 | O5: 8 | S5: V | T5: Quand je lance l’application, celle-ci me présente un menu principal composé des items « Nouvelle partie » et « Quitter ».
A6: Tous ces éléments sont à observer pour que le travail soit évaluable | S6: V | T6: Quand je sélectionne l’item « Quitter », l’application termine son exécution.
A7: Une archive .zip est déposée sur Moodle. | K7: 1 | S7: V | T7: Quand je sélectionne l’item « Nouvelle Partie », l’application navigue vers la vue PLAY_GAME, affiche la carte de la Terre du Milieu et le message « Le Mordor vs les Hommes », « Au tour du Mordor ».
A8: L'archive comporte un projet eclipse mentionnant le nom et le prénom (une infraction de nommage tolérée sur les 3 itérations). | K8: 1 | S8: AI-2 : Inspecter la carte de la Terre du Milieu
A9: Le projet respecte la structure demandée (présence des répertoires src et tests, fichiers sources dans les bons paquetages. -0,25 sur la note finale par fichier mal placé). | K9: 1 | L9: Pénalités: | M9: 0 | S9: X | T9: Soit une partie démarrée, la case active est de coordonnées (0,0) et la situation indique « PLAINE [1] ». Le sprite affiché est celui du Général du Mordor et sa description affiche « Sauron ».
A10: Les versions de Java, Junit et Eclipse sont conformes à celles demandées (une infraction tolérée sur les 3 itérations). | K10: 1 | S10: ! | T10: Soit une partie démarrée, quand j’appuie sur la touche directionnelle droite, la case active est de coordonnées (1,0). Quand j’appuie sur la touche directionnelle gauche, je reviens à la case active (0,0).
A11: Eclipse ne mentionne pas de problème de compilation (sauf problèmes de liaison au JDK, à JUnit 5). | K11: 1 | S11: ! | T11: Soit une partie démarrée, quand le joueur déplace la case active une fois vers le bas sur une forêt de la carte, la situation messages indique « FORÊT [2] ». Le sprite affiché est celui de Wargs et leur description indique « Wargs ».
A12: AI-1 - Lancer une partie | K12: 1 | L12: TA non-observés : | M12: 2.5 | N12: => Voir les remarques en fin de grille. | S12: ! | T12: Soit une partie démarrée, quand le joueur déplace la case active deux fois vers le bas sur une montagne de la carte, la situation messages indique « MONTAGNE [3] ». Il n’y a pas de sprite affiché sur la case.
A13: AI-2 - Inspecter la carte de la Terre du Milieu | K13: 0 | S13: AI-3 : Abandonner la partie
A14: AI-3 - Abandonner la partie | K14: 1 | S14: V | T14: Soit une partie lancée, quand j’appuie sur la touche « Esc », je reviens au menu principal.
A15: Acquis 1 : Programmer des énoncés de conception en Java selon les principes de la POO | K15: Observé | M15: Total Acquis 1 | N15: =SUM($K$17:$K$26) -> 10 | O15: 10
A16: Seuil de réussite (tous sont à valider pour obtenir l'acquis)
A17: [Prog. Procedurale] PMD relève au plus 2 méthodes trop longues et/ou trop complexes. | K17: 1 | M17: Les acquis n'ont pas été évalués car plusieurs tests d'acceptation n'ont pas été observés.
A18: [Cohésion] PMD relève au plus 2 classes comportant trop de champs. | K18: 1 | M18: Cependant, j'ai malgré tout indiqué certains points d'attention pour l'itération suivante.
A19: [Cohésion] PMD relève au plus 1 classe divine ou une classe de données. | K19: 1
A20: [Encapsulation] PMD relève au plus 2 champs d'accès autres que private. | K20: 1
A21: [Polymorphisme] PMD relève aucune alerte LooseCoupling. | K21: 1
A22: [Architecture] Les tests ArchUnit réussissent tous. | K22: 1
A23: [Encapsulation] Le principe de copies défensives est appliqué au moins deux fois, que ce soit dans les constructeurs ou pour les résultats retournés. | K23: 1
A24: [Masquage] Les classes métiers respectent la loi de Déméter (2 infractions tolérées). | K24: 1 | M24: ATTENTION : Plusieurs infractions constatées en raison, par exemple (liste non exhaustive) des accesseurs getMap, getMordorArmy et getCoalitionArmy de la classe HelmoDeepGame.
A25: [RDD] Les superviseurs n'exécutent pas les requêtes de l'utilisateur, elles les transmettent aux classes du domaine. | K25: 1
A26: [Polymorphisme] Les paramètres des constructeurs des superviseurs sont des types abstraits (interfaces ou classe abstraite). | K26: 1
A27: Acquis 2 : Valider les comportements des objets programmés par des tests unitaires | M27: Total Acquis 2 | N27: =SUM($K$29:$K$31) -> 3 | O27: 3
A28: Seuil de réussite (tous sont à valider pour obtenir l'acquis)
A29: Les classes du domaine sont validées par des tests unitaires. Les classes de test sont définis dans le même package (mais dans le répertoire de source "tests"). | K29: 1
A30: Quand je teste le package domains, j'obtiens une couverture d'au moins 90%. | K30: 1
A31: Tous les tests unitaires du package domains réussissent (1 test en échec toléré). | K31: 1
A32: Acquis 3 : Documenter son code | M32: Total Acquis 3 | N32: =SUM($K$34:$K36) -> 3 | O32: 3
A33: Seuil de réussite (tous sont à valider pour obtenir l'acquis)
A34: Les types et les méthodes publics sont documentés par de la javadoc inspirée par les énoncés (cf. PMD, 5 fautes tolérées). | K34: 1
A35: Les pré ou postconditions demandées figurent dans la javadoc et les réponses sont correctes. | K35: 1
A36: La CTT demandée est correctement évaluée dans la Javadoc. | K36: 1 | M36: ATTENTION, il y a plusieurs problèmes constatés !
M37: Tu dois clairement définir les lettres représentant les différentes quantités de données au début de ton évaluation de CTT.
M38: L'évaluation de la CTT doit être beaucoup plus détaillée sur la partie relative à ton code, notamment pour les méthodes de la classe HelmosDeepGameFactory.
M39: Il faut également tenir compte des CTT des structures de données manipulées.
A40: Acquis 4 : Justifier le choix d'une structure de données particulière | M40: Total Acquis 4 | N40: =SUM($K$42:$K44) -> 2 | O40: 2
...

Sheet Eval 2
A1: Activité intégrative : itération 2
M2: Acquis évalués : | N2: 1 | O2: 2 | P2: 3 | Q2: 4
A3: Nom et prénom : | C3: ='Eval 1'!C3 -> Thomas Hausmann | M3: Statut (Acquis=1, Non-acquis=0) | N3: =IF(OR(AND($O$5=($N$5+1),$K$10=0),$N$5=$O$5),TRUNC($N$15/$O$15),0) -> 1 | O3: =IF(OR(AND($O$5=($N$5+1),$K$10=0),$N$5=$O$5),TRUNC($N$27/$O$27),0) -> 1 | P3: =IF(OR(AND($O$5=($N$5+1),$K$10=0),$N$5=$O$5),TRUNC($N$32/$O$32),0) -> 1 | Q3: =IF(OR(AND($O$5=($N$5+1),$K$10=0),$N$5=$O$5),TRUNC($N$37/$O$37),0) -> 1
A5: Préalable | K5: Observé (oui=1, non = 0) | M5: Total préalable | N5: =IF($M$12<=2,SUM($K$7:$K$14), 0) -> 8 | O5: 8
A6: Tous ces éléments sont à observer pour que le travail soit évaluable
A7: Une archive .zip est déposée sur Moodle. | K7: 1
A8: L'archive comporte un projet eclipse mentionnant le nom et le prénom (une infraction de nommage tolérée sur les 3 itérations). | K8: 1
A9: Le projet respecte la structure demandée (présence des répertoires src et tests, fichiers sources dans les bons paquetages. -0,25 sur la note finale par fichier mal placé). | K9: 1 | L9: Pénalités: | M9: 0
A10: Les versions de Java, Junit et Eclipse sont conformes à celles demandées (une infraction tolérée sur les 3 itérations). | K10: 1
A11: Eclipse ne mentionne pas de problème de compilation (sauf problèmes de liaison au JDK, à JUnit 5). | K11: 1
A12: AI-4 - ??? | K12: 1 | L12: TA non-observés : | M12: 0
A13: AI-5 - ??? | K13: 1
A14: AI-6 - ??? | K14: 1
A15: Acquis 1 : Programmer des énoncés de conception en Java selon les principes de la POO | K15: Observé | M15: Total Acquis 1 | N15: =SUM($K$17:$K$26) -> 10 | O15: 10
A16: Seuil de réussite (tous sont à valider pour obtenir l'acquis)
A17: [Prog. Procedurale] PMD relève au plus 2 méthodes trop longues et/ou trop complexes. | K17: 1
A18: [Cohésion] PMD relève au plus 2 classes comportant trop de champs. | K18: 1
A19: [Cohésion] PMD relève au plus 1 classe divine ou une classe de données. | K19: 1
A20: [Encapsulation] PMD relève au plus 2 champs d'accès autres que private. | K20: 1
A21: [Polymorphisme] PMD relève aucune alerte LooseCoupling. | K21: 1
A22: [Architecture] Les tests ArchUnit réussissent tous. | K22: 1
A23: [Encapsulation] Le principe de copies défensives est appliqué au moins deux fois, que ce soit dans les constructeurs ou pour les résultats retournés. | K23: 1
A24: [Masquage] Les classes métiers respectent la loi de Déméter (2 infractions tolérées). | K24: 1
A25: [RDD] Les superviseurs n'exécutent pas les requêtes de l'utilisateur, elles les transmettent aux classes du domaine. | K25: 1
A26: [Polymorphisme] Les paramètres des constructeurs des superviseurs sont des types abstraits (interfaces ou classe abstraite). | K26: 1
A27: Acquis 2 : Valider les comportements des objets programmés par des tests unitaires | M27: Total Acquis 2 | N27: =SUM($K$29:$K$31) -> 3 | O27: 3
A28: Seuil de réussite (tous sont à valider pour obtenir l'acquis)
A29: Les classes du domaine sont validées par des tests unitaires. Les classes de test sont définis dans le même package (mais dans le répertoire de source "tests"). | K29: 1
A30: Quand je teste le package domains, j'obtiens une couverture d'au moins 90%. | K30: 1
A31: Tous les tests unitaires du package domains réussissent (1 test en échec toléré). | K31: 1
A32: Acquis 3 : Documenter son code | M32: Total Acquis 3 | N32: =SUM($K$34:$K36) -> 3 | O32: 3
A33: Seuil de réussite (tous sont à valider pour obtenir l'acquis)
A34: Les types et les méthodes publics sont documentés par de la javadoc inspirée par les énoncés (cf. PMD, 5 fautes tolérées). | K34: 1
A35: Les pré ou postconditions demandées figurent dans la javadoc et les réponses sont correctes. | K35: 1
A36: La CTT demandée est correctement évaluée dans la Javadoc. | K36: 1
A37: Acquis 4 : Justifier le choix d'une structure de données particulière | M37: Total Acquis 4 | N37: =SUM($K$39:$K40) -> 2 | O37: 2
A38: Seuil de réussite (tous sont à valider pour obtenir l'acquis)
A39: Les choix de type de collection sont correctement documentés dans le code. | K39: 1
A40: Les choix d'implémentation sont correctement documentés dans le code. | K40: 1
A41: Degré de maitrise | M41: Total degré de mait. | N41: =IF(SUM($N$3:$Q$3)>3,SUM($K$43:$K51),0) -> 9 | O41: 9
...

Sheet Eval 3
A1: Activité intégrative : itération 3
M2: Acquis évalués : | N2: 1 | O2: 2 | P2: 3 | Q2: 4
A3: Nom et prénom : | C3: ='Eval 1'!C3 -> Thomas Hausmann | M3: Statut (Acquis=1, Non-acquis=0) | N3: =IF(OR(AND($O$5=($N$5+1),$K$10=0),$N$5=$O$5),TRUNC($N$15/$O$15),0) -> 1 | O3: =IF(OR(AND($O$5=($N$5+1),$K$10=0),$N$5=$O$5),TRUNC($N$27/$O$27),0) -> 1 | P3: =IF(OR(AND($O$5=($N$5+1),$K$10=0),$N$5=$O$5),TRUNC($N$32/$O$32),0) -> 1 | Q3: =IF(OR(AND($O$5=($N$5+1),$K$10=0),$N$5=$O$5),TRUNC($N$37/$O$37),0) -> 1
A5: Préalable | K5: Observé (oui=1, non = 0) | M5: Total préalable | N5: =IF($M$12<=2,SUM($K$7:$K$14), 0) -> 8 | O5: 8
A6: Tous ces éléments sont à observer pour que le travail soit évaluable
A7: Une archive .zip est déposée sur Moodle. | K7: 1
A8: L'archive comporte un projet eclipse mentionnant le nom et le prénom (une infraction de nommage tolérée sur les 3 itérations). | K8: 1
A9: Le projet respecte la structure demandée (présence des répertoires src et tests, fichiers sources dans les bons paquetages. -0,25 sur la note finale par fichier mal placé). | K9: 1 | L9: Pénalités: | M9: 0
A10: Les versions de Java, Junit et Eclipse sont conformes à celles demandées (une infraction tolérée sur les 3 itérations). | K10: 1
A11: Eclipse ne mentionne pas de problème de compilation (sauf problèmes de liaison au JDK, à JUnit 5). | K11: 1
A12: AI-7 - ??? | K12: 1 | L12: TA non-observés : | M12: 0
A13: AI-8 - ??? | K13: 1
A14: AI-9 - ??? | K14: 1
A15: Acquis 1 : Programmer des énoncés de conception en Java selon les principes de la POO | K15: Observé | M15: Total Acquis 1 | N15: =SUM($K$17:$K$26) -> 10 | O15: 10
A16: Seuil de réussite (tous sont à valider pour obtenir l'acquis)
A17: [Prog. Procedurale] PMD relève au plus 2 méthodes trop longues et/ou trop complexes. | K17: 1
A18: [Cohésion] PMD relève au plus 2 classes comportant trop de champs. | K18: 1
A19: [Cohésion] PMD relève au plus 1 classe divine ou une classe de données. | K19: 1
A20: [Encapsulation] PMD relève au plus 2 champs d'accès autres que private. | K20: 1
A21: [Polymorphisme] PMD relève aucune alerte LooseCoupling. | K21: 1
A22: [Architecture] Les tests ArchUnit réussissent tous. | K22: 1
A23: [Encapsulation] Le principe de copies défensives est appliqué au moins deux fois, que ce soit dans les constructeurs ou pour les résultats retournés. | K23: 1
A24: [Masquage] Les classes métiers respectent la loi de Déméter (2 infractions tolérées). | K24: 1
A25: [RDD] Les superviseurs n'exécutent pas les requêtes de l'utilisateur, elles les transmettent aux classes du domaine. | K25: 1
A26: [Polymorphisme] Les paramètres des constructeurs des superviseurs sont des types abstraits (interfaces ou classe abstraite). | K26: 1
A27: Acquis 2 : Valider les comportements des objets programmés par des tests unitaires | M27: Total Acquis 2 | N27: =SUM($K$29:$K$31) -> 3 | O27: 3
A28: Seuil de réussite (tous sont à valider pour obtenir l'acquis)
A29: Les classes du domaine sont validées par des tests unitaires. Les classes de test sont définis dans le même package (mais dans le répertoire de source "tests"). | K29: 1
A30: Quand je teste le package domains, j'obtiens une couverture d'au moins 90%. | K30: 1
A31: Tous les tests unitaires du package domains réussissent (1 test en échec toléré). | K31: 1
A32: Acquis 3 : Documenter son code | M32: Total Acquis 3 | N32: =SUM($K$34:$K36) -> 3 | O32: 3
A33: Seuil de réussite (tous sont à valider pour obtenir l'acquis)
A34: Les types et les méthodes publics sont documentés par de la javadoc inspirée par les énoncés (cf. PMD, 5 fautes tolérées). | K34: 1
A35: Les pré ou postconditions demandées figurent dans la javadoc et les réponses sont correctes. | K35: 1
A36: La CTT demandée est correctement évaluée dans la Javadoc. | K36: 1
A37: Acquis 4 : Justifier le choix d'une structure de données particulière | M37: Total Acquis 4 | N37: =SUM($K$39:$K40) -> 2 | O37: 2
A38: Seuil de réussite (tous sont à valider pour obtenir l'acquis)
A39: Les choix de type de collection sont correctement documentés dans le code. | K39: 1
A40: Les choix d'implémentation sont correctement documentés dans le code. | K40: 1
A41: Degré de maitrise | M41: Total degré de mait. | N41: =IF(SUM($N$3:$Q$3)>3,SUM($K$43:$K51),0) -> 9 | O41: 9
...

Sheet Acquis5
A1: Libellé | C1: Observé | D1: Pondération | I1: TI | J1: 0
A2: Défense orale: présentation fonctionnelle (~2min) | D2: 0.3 | F2: Nbr. Éléments observés | G2: =COUNTIF($B$3:$B$4,"=1") -> 2 | I2: I | J2: 0.35
A3: La présentation démontre une préparation (scénario prévu à l'avance, montrant un ou deux cas de figure intéressants, écrans présentant des données réelles et représentatives, etc.). | B3: 1 | F3: Nbr. Éléments total | G3: 2 | I3: S | J3: 0.5
A4: Le support est de qualité (diaporama et code lisibles), la voix est suffisamment audible, absence de temps morts, etc… | B4: 1 | F4: Niveau obtenu | G4: =G2/G3 -> 1 | I4: B | J4: 0.7
A5: Défense orale: présentation technique (~3min) | D5: 0.4 | F5: Nbr. Éléments observés | G5: =COUNTIF($B$6:$B$9,"=1") -> 4 | I5: TB | J5: 1
A6: La présentation explique les choix de réalisation d'un des algorithmes du jeu au choix | B6: 1 | D6: Présentation du choix des options du menu... | F6: Nbr. Éléments total | G6: 4
A7: La présentation explique la CTT d'un des algorithmes du jeu au choix | B7: 1 | F7: Niveau obtenu | G7: =G5/G6 -> 1
A8: La présentation explique un choix de collection (type et implémentation) | B8: 1
A9: Le vocabulaire utilisé est adéquat et précis (principes orientés objet, complexités, …) | B9: 1
A10: Défense orale: conclusion (~2 min) | D10: 0.3 | F10: Nbr. Éléments observés | G10: =COUNTIF($B$11:$B$14,"=1") -> 4
A11: La conclusion mentionne le degré de réalistion du projet et met en évidence ce qui n'a pas été achevé. | B11: 1 | F11: Nbr. Éléments total | G11: 4
A12: La conclusion mentionne les apports de l'activité du point de vue personnel (ex:je m'organise mieux) et technique (ex:je comprends enfin ce qu'est une boucle) | B12: 1 | F12: Niveau obtenu | G12: =G10/G11 -> 1
A13: La conclusion énonce plusieurs difficultés rencontrées et des pistes de solution pour y remédier (ex: lire un énoncé, donner des responsabilités aux classes, ...). | B13: 1
A14: La conclusion mentionne des pistes à explorer pour améliorer sa productivité (ex:travailler la Poo, faire plus de tests unitaires, etc.) et les bénéfices attendus. | B14: 1
A17: Pénalité si parcours "commu" pas finalisé avant la défense ou de qualité insuffisante | B17: 0 | C17: De 1 à 10 points de pénalité
A18: Inversement, la vidéo déposée sur HELMo Learn peut permettre de valider l'acquis 5 si la défense orale était mauvaise
A19: Note sur 20 | B19: =MROUND((G4*D2+G7*D5+G12*D10)*20,0.1)-B17 -> 20

Sheet Recap1s
A1: Récapitulatif
A3: Nom et prénom : | C3: ='Eval 1'!C3 -> Thomas Hausmann
B5: Acquis 1 | C5: Acquis 2 | D5: Acquis 3 | E5: Acquis 4 | G5: Acquis 5
A6: Eval 1 | B6: ='Eval 1'!N$3 -> 0 | C6: ='Eval 1'!O$3 -> 0 | D6: ='Eval 1'!P$3 -> 0 | E6: ='Eval 1'!Q$3 -> 0 | G6: =IF(Acquis5!$B19<10,0,1) -> 1
A7: Eval 2 | B7: ='Eval 2'!$N$3 -> 1 | C7: ='Eval 2'!$O$3 -> 1 | D7: ='Eval 2'!$P$3 -> 1 | E7: ='Eval 2'!$Q$3 -> 1 | H7: Oral si au moins deux acquis validés parmi les 4 ; | L7: =IF(COUNTIF(B10:E10,">=2")>=2,TRUE,FALSE) -> TRUE
A8: Eval 3 | B8: ='Eval 3'!$N$3 -> 1 | C8: ='Eval 3'!$O$3 -> 1 | D8: ='Eval 3'!$P$3 -> 1 | E8: ='Eval 3'!$Q$3 -> 1 | H8: • Si deux acquis doivent encore être validés, l’un des deux doit avoir été observé préalablement ; | L8: =IF(COUNTIF(B10:E10,">=2")=2,IF(COUNTIF(B10:E10,"=1")>=1,TRUE,FALSE),IF(COUNTIF(B10:E10,">=2"),TRUE,FALSE)) -> TRUE
A9: Validation via défense orale éventuelle* (0, 1 ou 2) | B9: 0 | C9: 0 | D9: 0 | E9: 0 | F9: =IF(AND(L7,L8,L9),"Accès à l'oral","Pas d'accès à l'oral") -> Accès à l'oral | H9: • Si un seul acquis doit être validé, il n’est pas nécessaire qu’il ait déjà été observé. | L9: =IF(COUNTIF(B10:E10,">=2")>=3,TRUE,L8) -> TRUE
A10: Total | B10: =SUM(B6:B9) -> 2 | C10: =SUM(C6:C9) -> 2 | D10: =SUM(D6:D9) -> 2 | E10: =SUM(E6:E9) -> 2
A11: Appréciation suite à l'oral(-2 à +2) | B11: 0
A12: Pénalités des eval 1 à 3 | B12: ='Eval 1'!M9+'Eval 2'!M9+'Eval 3'!M9 -> 0
A13: Note finale | B13: =MROUND(IF(AND(B10>1,C10>1,D10>1,E10>1,G6>0),B11-B12+10+SUM('Eval 1'!N45+'Eval 2'!N41+'Eval 3'!N41+Acquis5!B19/2)/SUM('Eval 1'!O45+'Eval 2'!O41+'Eval 3'!O41+10)*10,MIN(7,MAX(5,SUM(B10:E10,C14)))),1) -> 18
A14: Nombre d'itérations rendues | C14: ='Eval 1'!K7+'Eval 2'!K7+'Eval 3'!K7 -> 3
A16: *L'étudiant répond de façon satisfaisante aux questions, ce qui lui permet de valider certains acquis manquants
A17: Questions posées:

Sheet Eval 4
A1: Activité intégrative : itération 4
M2: Acquis évalués : | N2: 1 | O2: 2 | P2: 3 | Q2: 4
A3: Nom et prénom : | C3: ='Eval 1'!C3 -> Thomas Hausmann | M3: Statut (Acquis=1, Non-acquis=0) | N3: =IF(OR(AND($O$5=($N$5+1),$K$10=0),$N$5=$O$5),TRUNC($N$15/$O$15),0) -> 1 | O3: =IF(OR(AND($O$5=($N$5+1),$K$10=0),$N$5=$O$5),TRUNC($N$27/$O$27),0) -> 1 | P3: =IF(OR(AND($O$5=($N$5+1),$K$10=0),$N$5=$O$5),TRUNC($N$32/$O$32),0) -> 1 | Q3: =IF(OR(AND($O$5=($N$5+1),$K$10=0),$N$5=$O$5),TRUNC($N$37/$O$37),0) -> 1
A5: Préalable | K5: Observé (oui=1, non = 0) | M5: Total préalable | N5: =IF($M$12<=4,SUM($K$7:$K$14), 0) -> 8 | O5: 8
A6: Tous ces éléments sont à observer pour que le travail soit évaluable
A7: Une archive .zip est déposée sur Moodle. | K7: 1
A8: L'archive comporte un projet eclipse mentionnant le nom et le prénom (une infraction de nommage tolérée sur les 3 itérations) | K8: 1
A9: Le projet respecte la structure demandée (présence des répertoires src et tests, fichiers sources dans les bons paquetages. -0,25 sur la note finale par fichier mal placé) | K9: 1 | L9: Pénalités: | M9: 0
A10: Les versions de Java, Junit et Eclipse sont conformes à celles demandées (une infraction tolérée sur les 3 itérations) | K10: 1
A11: Eclipse ne mentionne pas de problème de compilation (sauf problèmes de liaison au JDK, à JUnit 5) | K11: 1
A12: AI-1 - Lancer une partie | K12: 1 | L12: TA non-observés : | M12: 0 | N12: Tol : | O12: 4
A13: AI-2 - Inspecter la carte | K13: 1
A14: AI-3 - Quitter la partie | K14: 1
A15: Acquis 1 : Programmer des énoncés de conception en Java selon les principes de la POO | K15: Observé | M15: Total Acquis 1 | N15: =SUM($K$17:$K$26) -> 10 | O15: 10
A16: Seuil de réussite (tous sont à valider pour obtenir l'acquis)
A17: [Prog. Procedurale] PMD relève au plus 2 méthodes trop longues et/ou trop complexes | K17: 1 | M17: Problèmes : NcssCount in ./src/chrominox/domains/scoring/ByZonesPointsStrategy.java at line 69 : The method 'computePointsFor(ChroMosaic, Chromino, Coordinate)' has a NCSS line count of 22. CyclomaticComplexity in ./src/chrominox/domains/scoring/ByZonesPointsStrategy.java at line 69 : The method 'computePointsFor(ChroMosaic, Chromino, Coordinate)' has a cyclomatic complexity of 10.
A18: [Cohésion] PMD relève au plus 2 classes comportant trop de champs. | K18: 1
A19: [Cohésion] PMD relève au plus 1 classe divine ou une classe de données | K19: 1
A20: [Encapsulation] PMD relève au plus 2 champs d'accès autres que private | K20: 1
A21: [Polymorphisme] PMD relève aucune alerte LooseCoupling | K21: 1
A22: [Architecture] Les tests ArchUnit réussissent tous | K22: 1
A23: [Encapsulation] Le principe de copies défensives est appliqué au moins deux fois, que ce soit dans les constructeurs ou pour les résultats retournés. | K23: 1
A24: [Masquage] Les classes métiers respectent la loi de Déméter (2 infractions tolérées) | K24: 1
A25: [RDD] Les superviseurs n'exécutent pas les requêtes de l'utilisateur, elles les transmettent aux classes du domaine. | K25: 1
A26: [Polymorphisme] Les paramètres des constructeurs des superviseurs sont des types abstraits (interfaces ou classe abstraite) | K26: 1
A27: Acquis 2 : Valider les comportements des objets programmés par des tests unitaires | M27: Total Acquis 2 | N27: =SUM($K$29:$K$31) -> 3 | O27: 3
A28: Seuil de réussite (tous sont à valider pour obtenir l'acquis)
A29: Les classes du domaine sont validées par des tests unitaires. Les classes de test sont définis dans le même package (mais dans le répertoire de source "tests"). | K29: 1
A30: Quand je teste le package domains, j'obtiens une couverture d'au moins 90%. | K30: 1
A31: Tous les tests unitaires du package domains réussissent. (1 test en échec toléré) | K31: 1
A32: Acquis 3 : Documenter son code | M32: Total Acquis 3 | N32: =SUM($K$34:$K36) -> 3 | O32: 3
A33: Seuil de réussite (tous sont à valider pour obtenir l'acquis)
A34: Les types et les méthodes publics sont documentés par de la javadoc inspirée par les énoncés (cf. PMD, 5 fautes tolérées) | K34: 1
A35: Les pré ou postconditions demandées figurent dans la javadoc et les réponses sont correctes. | K35: 1
A36: La CTT demandée est correctement évaluée dans la Javadoc. | K36: 1
A37: Acquis 4 : Justifier le choix d'une structure de données particulière | M37: Total Acquis 4 | N37: =SUM($K$39:$K40) -> 2 | O37: 2
A38: Seuil de réussite (tous sont à valider pour obtenir l'acquis)
A39: Les choix de type de collection sont correctement documentés dans le code. | K39: 1
A40: Les choix d'implémentation sont correctement documentés dans le code. | K40: 1
A41: Degré de maitrise | M41: Total degré de mait. | N41: =IF(SUM($N$3:$Q$3)>3,SUM($K$43:$K51),0) -> 9 | O41: 9
...

Sheet Recap2s
A1: Récapitulatif
A3: Nom et prénom : | B3: ='Eval 1'!C3 -> Thomas Hausmann
B5: Acquis 1 | C5: Acquis 2 | D5: Acquis 3 | E5: Acquis 4 | G5: Acquis 5
A6: Eval 1 à 3 | B6: =Recap1s!B10 -> 2 | C6: =Recap1s!C10 -> 2 | D6: =Recap1s!D10 -> 2 | E6: =Recap1s!E10 -> 2 | G6: =IF(Acquis5!B19<10,0,1) -> 1 | H6: En seconde session, la seule vidéo de présentation permet de valider l'acquis 5
A7: Eval 4 | B7: ='Eval 4'!N3 -> 1 | C7: ='Eval 4'!O3 -> 1 | D7: ='Eval 4'!P3 -> 1 | E7: ='Eval 4'!Q3 -> 1 | H7: Oral si 3 acquis différents sont observés dont un acquis observé sur l’itération 4 | N7: =IF(AND(COUNTIF(B9:E9,"=0")<=1,COUNTIF(B7:E7,"=1")>=1),TRUE,FALSE) -> TRUE
A8: Validation via défense orale éventuelle* (0, 1 ou 2) | B8: 0 | C8: 0 | D8: 0 | E8: 0 | F8: =IF(AND(N7,N8),"Accès à l'oral","Pas d'accès à l'oral") -> Accès à l'oral | H8: et si certains acquis n'ont jamais été observés, l'un d'eux doit être observé sur l'itération 4. | N8: =IF(N9=0,TRUE,IF(O8,TRUE,IF(P8,TRUE,IF(Q8,TRUE,R8)))) -> TRUE | O8: =IF(O9=1,TRUE,FALSE) -> FALSE | P8: =IF(P9=1,TRUE,FALSE) -> FALSE | Q8: =IF(Q9=1,TRUE,FALSE) -> FALSE | R8: =IF(R9=1,TRUE,FALSE) -> FALSE
A9: Total | B9: =SUM(B6:B8) -> 3 | C9: =SUM(C6:C8) -> 3 | D9: =SUM(D6:D8) -> 3 | E9: =SUM(E6:E8) -> 3 | K9: Nombre d'acquis jamais observés sur 1s | N9: =COUNTIF(B6:E6,"=0") -> 0 | O9: =_xlfn.IFNA(HLOOKUP(0,B6:$E$7,2,FALSE),2) -> 2 | P9: =_xlfn.IFNA(HLOOKUP(0,C6:$E$7,2,FALSE),2) -> 2 | Q9: =_xlfn.IFNA(HLOOKUP(0,D6:$E$7,2,FALSE),2) -> 2 | R9: =_xlfn.IFNA(HLOOKUP(0,E6:$E$7,2,FALSE),2) -> 2
A10: Appréciation suite à l'oral(-2 à +2) | B10: 0
A11: Pénalités des eval 1 à 4 | B11: ='Eval 4'!M9 -> 0
A12: Note finale | B12: =MROUND(IF(AND(B9>1,C9>1,D9>1,E9>1,G6>0),B10-B11+10+SUM('Eval 1'!N45+'Eval 2'!N41+'Eval 3'!N41+'Eval 4'!N41+Acquis5!B19/2)/SUM('Eval 1'!O45+'Eval 2'!O41+'Eval 3'!O41+'Eval 4'!O41+10)*10,MIN(7,MAX(5,SUM(B9:E9,C14)))),1) -> 18
A14: Nombre d'itérations rendues | C14: ='Eval 1'!K7+'Eval 2'!K7+'Eval 3'!K7+'Eval 4'!K7 -> 4
A16: *L'étudiant répond de façon satisfaisante aux questions, ce qui lui permet de valider certains acquis manquants
